2019-07-04 18:06:04,180 - base.py[line:152] - WARNING: Not Found: /favicon.ico
2019-07-04 18:07:56,693 - exception.py[line:124] - ERROR: Internal Server Error: /monitor/index
Traceback (most recent call last):
  File "D:\Anaconda3\lib\site-packages\django\core\handlers\exception.py", line 39, in inner
    response = get_response(request)
  File "D:\Anaconda3\lib\site-packages\django\core\handlers\base.py", line 187, in _get_response
    response = self.process_exception_by_middleware(e, request)
  File "D:\Anaconda3\lib\site-packages\django\core\handlers\base.py", line 185, in _get_response
    response = wrapped_callback(request, *callback_args, **callback_kwargs)
  File "D:\new\07_code_project\mydjango\monitor\views.py", line 22, in index
    need,time = c.comCronNow(crontab)
  File "D:\new\07_code_project\mydjango\util\crontabUtil.py", line 11, in comCronNow
    print('str_time_now' + str_time_now)
TypeError: must be str, not datetime.datetime
2019-07-04 18:07:56,693 - exception.py[line:124] - ERROR: Internal Server Error: /monitor/index
Traceback (most recent call last):
  File "D:\Anaconda3\lib\site-packages\django\core\handlers\exception.py", line 39, in inner
    response = get_response(request)
  File "D:\Anaconda3\lib\site-packages\django\core\handlers\base.py", line 187, in _get_response
    response = self.process_exception_by_middleware(e, request)
  File "D:\Anaconda3\lib\site-packages\django\core\handlers\base.py", line 185, in _get_response
    response = wrapped_callback(request, *callback_args, **callback_kwargs)
  File "D:\new\07_code_project\mydjango\monitor\views.py", line 22, in index
    need,time = c.comCronNow(crontab)
  File "D:\new\07_code_project\mydjango\util\crontabUtil.py", line 11, in comCronNow
    print('str_time_now' + str_time_now)
TypeError: must be str, not datetime.datetime
2019-07-04 18:08:53,438 - exception.py[line:124] - ERROR: Internal Server Error: /monitor/index
Traceback (most recent call last):
  File "D:\Anaconda3\lib\site-packages\django\core\handlers\exception.py", line 39, in inner
    response = get_response(request)
  File "D:\Anaconda3\lib\site-packages\django\core\handlers\base.py", line 187, in _get_response
    response = self.process_exception_by_middleware(e, request)
  File "D:\Anaconda3\lib\site-packages\django\core\handlers\base.py", line 185, in _get_response
    response = wrapped_callback(request, *callback_args, **callback_kwargs)
  File "D:\new\07_code_project\mydjango\monitor\views.py", line 26, in index
    if checkTaskRec(name,time):
  File "D:\new\07_code_project\mydjango\monitor\views.py", line 45, in checkTaskRec
    for rec in TaskRec.objects.filter(name=name):
  File "D:\Anaconda3\lib\site-packages\django\db\models\manager.py", line 85, in manager_method
    return getattr(self.get_queryset(), name)(*args, **kwargs)
  File "D:\Anaconda3\lib\site-packages\django\db\models\query.py", line 796, in filter
    return self._filter_or_exclude(False, *args, **kwargs)
  File "D:\Anaconda3\lib\site-packages\django\db\models\query.py", line 814, in _filter_or_exclude
    clone.query.add_q(Q(*args, **kwargs))
  File "D:\Anaconda3\lib\site-packages\django\db\models\sql\query.py", line 1227, in add_q
    clause, _ = self._add_q(q_object, self.used_aliases)
  File "D:\Anaconda3\lib\site-packages\django\db\models\sql\query.py", line 1253, in _add_q
    allow_joins=allow_joins, split_subq=split_subq,
  File "D:\Anaconda3\lib\site-packages\django\db\models\sql\query.py", line 1133, in build_filter
    lookups, parts, reffed_expression = self.solve_lookup_type(arg)
  File "D:\Anaconda3\lib\site-packages\django\db\models\sql\query.py", line 1019, in solve_lookup_type
    _, field, _, lookup_parts = self.names_to_path(lookup_splitted, self.get_meta())
  File "D:\Anaconda3\lib\site-packages\django\db\models\sql\query.py", line 1327, in names_to_path
    "Choices are: %s" % (name, ", ".join(available)))
django.core.exceptions.FieldError: Cannot resolve keyword 'name' into field. Choices are: id, lastGeneTime, taskCount, taskName, wc_l
2019-07-04 18:08:53,438 - exception.py[line:124] - ERROR: Internal Server Error: /monitor/index
Traceback (most recent call last):
  File "D:\Anaconda3\lib\site-packages\django\core\handlers\exception.py", line 39, in inner
    response = get_response(request)
  File "D:\Anaconda3\lib\site-packages\django\core\handlers\base.py", line 187, in _get_response
    response = self.process_exception_by_middleware(e, request)
  File "D:\Anaconda3\lib\site-packages\django\core\handlers\base.py", line 185, in _get_response
    response = wrapped_callback(request, *callback_args, **callback_kwargs)
  File "D:\new\07_code_project\mydjango\monitor\views.py", line 26, in index
    if checkTaskRec(name,time):
  File "D:\new\07_code_project\mydjango\monitor\views.py", line 45, in checkTaskRec
    for rec in TaskRec.objects.filter(name=name):
  File "D:\Anaconda3\lib\site-packages\django\db\models\manager.py", line 85, in manager_method
    return getattr(self.get_queryset(), name)(*args, **kwargs)
  File "D:\Anaconda3\lib\site-packages\django\db\models\query.py", line 796, in filter
    return self._filter_or_exclude(False, *args, **kwargs)
  File "D:\Anaconda3\lib\site-packages\django\db\models\query.py", line 814, in _filter_or_exclude
    clone.query.add_q(Q(*args, **kwargs))
  File "D:\Anaconda3\lib\site-packages\django\db\models\sql\query.py", line 1227, in add_q
    clause, _ = self._add_q(q_object, self.used_aliases)
  File "D:\Anaconda3\lib\site-packages\django\db\models\sql\query.py", line 1253, in _add_q
    allow_joins=allow_joins, split_subq=split_subq,
  File "D:\Anaconda3\lib\site-packages\django\db\models\sql\query.py", line 1133, in build_filter
    lookups, parts, reffed_expression = self.solve_lookup_type(arg)
  File "D:\Anaconda3\lib\site-packages\django\db\models\sql\query.py", line 1019, in solve_lookup_type
    _, field, _, lookup_parts = self.names_to_path(lookup_splitted, self.get_meta())
  File "D:\Anaconda3\lib\site-packages\django\db\models\sql\query.py", line 1327, in names_to_path
    "Choices are: %s" % (name, ", ".join(available)))
django.core.exceptions.FieldError: Cannot resolve keyword 'name' into field. Choices are: id, lastGeneTime, taskCount, taskName, wc_l
2019-07-04 18:09:46,409 - exception.py[line:124] - ERROR: Internal Server Error: /monitor/index
Traceback (most recent call last):
  File "D:\Anaconda3\lib\site-packages\django\core\handlers\exception.py", line 39, in inner
    response = get_response(request)
  File "D:\Anaconda3\lib\site-packages\django\core\handlers\base.py", line 187, in _get_response
    response = self.process_exception_by_middleware(e, request)
  File "D:\Anaconda3\lib\site-packages\django\core\handlers\base.py", line 185, in _get_response
    response = wrapped_callback(request, *callback_args, **callback_kwargs)
  File "D:\new\07_code_project\mydjango\monitor\views.py", line 27, in index
    if checkTaskRec(name,time):
  File "D:\new\07_code_project\mydjango\monitor\views.py", line 46, in checkTaskRec
    for rec in TaskRec.objects.filter(name=name):
  File "D:\Anaconda3\lib\site-packages\django\db\models\manager.py", line 85, in manager_method
    return getattr(self.get_queryset(), name)(*args, **kwargs)
  File "D:\Anaconda3\lib\site-packages\django\db\models\query.py", line 796, in filter
    return self._filter_or_exclude(False, *args, **kwargs)
  File "D:\Anaconda3\lib\site-packages\django\db\models\query.py", line 814, in _filter_or_exclude
    clone.query.add_q(Q(*args, **kwargs))
  File "D:\Anaconda3\lib\site-packages\django\db\models\sql\query.py", line 1227, in add_q
    clause, _ = self._add_q(q_object, self.used_aliases)
  File "D:\Anaconda3\lib\site-packages\django\db\models\sql\query.py", line 1253, in _add_q
    allow_joins=allow_joins, split_subq=split_subq,
  File "D:\Anaconda3\lib\site-packages\django\db\models\sql\query.py", line 1133, in build_filter
    lookups, parts, reffed_expression = self.solve_lookup_type(arg)
  File "D:\Anaconda3\lib\site-packages\django\db\models\sql\query.py", line 1019, in solve_lookup_type
    _, field, _, lookup_parts = self.names_to_path(lookup_splitted, self.get_meta())
  File "D:\Anaconda3\lib\site-packages\django\db\models\sql\query.py", line 1327, in names_to_path
    "Choices are: %s" % (name, ", ".join(available)))
django.core.exceptions.FieldError: Cannot resolve keyword 'name' into field. Choices are: id, lastGeneTime, taskCount, taskName, wc_l
2019-07-04 18:09:46,409 - exception.py[line:124] - ERROR: Internal Server Error: /monitor/index
Traceback (most recent call last):
  File "D:\Anaconda3\lib\site-packages\django\core\handlers\exception.py", line 39, in inner
    response = get_response(request)
  File "D:\Anaconda3\lib\site-packages\django\core\handlers\base.py", line 187, in _get_response
    response = self.process_exception_by_middleware(e, request)
  File "D:\Anaconda3\lib\site-packages\django\core\handlers\base.py", line 185, in _get_response
    response = wrapped_callback(request, *callback_args, **callback_kwargs)
  File "D:\new\07_code_project\mydjango\monitor\views.py", line 27, in index
    if checkTaskRec(name,time):
  File "D:\new\07_code_project\mydjango\monitor\views.py", line 46, in checkTaskRec
    for rec in TaskRec.objects.filter(name=name):
  File "D:\Anaconda3\lib\site-packages\django\db\models\manager.py", line 85, in manager_method
    return getattr(self.get_queryset(), name)(*args, **kwargs)
  File "D:\Anaconda3\lib\site-packages\django\db\models\query.py", line 796, in filter
    return self._filter_or_exclude(False, *args, **kwargs)
  File "D:\Anaconda3\lib\site-packages\django\db\models\query.py", line 814, in _filter_or_exclude
    clone.query.add_q(Q(*args, **kwargs))
  File "D:\Anaconda3\lib\site-packages\django\db\models\sql\query.py", line 1227, in add_q
    clause, _ = self._add_q(q_object, self.used_aliases)
  File "D:\Anaconda3\lib\site-packages\django\db\models\sql\query.py", line 1253, in _add_q
    allow_joins=allow_joins, split_subq=split_subq,
  File "D:\Anaconda3\lib\site-packages\django\db\models\sql\query.py", line 1133, in build_filter
    lookups, parts, reffed_expression = self.solve_lookup_type(arg)
  File "D:\Anaconda3\lib\site-packages\django\db\models\sql\query.py", line 1019, in solve_lookup_type
    _, field, _, lookup_parts = self.names_to_path(lookup_splitted, self.get_meta())
  File "D:\Anaconda3\lib\site-packages\django\db\models\sql\query.py", line 1327, in names_to_path
    "Choices are: %s" % (name, ", ".join(available)))
django.core.exceptions.FieldError: Cannot resolve keyword 'name' into field. Choices are: id, lastGeneTime, taskCount, taskName, wc_l
2019-07-04 18:11:24,307 - exception.py[line:124] - ERROR: Internal Server Error: /monitor/index
Traceback (most recent call last):
  File "D:\Anaconda3\lib\site-packages\django\core\handlers\exception.py", line 39, in inner
    response = get_response(request)
  File "D:\Anaconda3\lib\site-packages\django\core\handlers\base.py", line 187, in _get_response
    response = self.process_exception_by_middleware(e, request)
  File "D:\Anaconda3\lib\site-packages\django\core\handlers\base.py", line 185, in _get_response
    response = wrapped_callback(request, *callback_args, **callback_kwargs)
  File "D:\new\07_code_project\mydjango\monitor\views.py", line 27, in index
    if checkTaskRec(name,time):
  File "D:\new\07_code_project\mydjango\monitor\views.py", line 46, in checkTaskRec
    for rec in TaskRec.objects.filter(name=name):
  File "D:\Anaconda3\lib\site-packages\django\db\models\manager.py", line 85, in manager_method
    return getattr(self.get_queryset(), name)(*args, **kwargs)
  File "D:\Anaconda3\lib\site-packages\django\db\models\query.py", line 796, in filter
    return self._filter_or_exclude(False, *args, **kwargs)
  File "D:\Anaconda3\lib\site-packages\django\db\models\query.py", line 814, in _filter_or_exclude
    clone.query.add_q(Q(*args, **kwargs))
  File "D:\Anaconda3\lib\site-packages\django\db\models\sql\query.py", line 1227, in add_q
    clause, _ = self._add_q(q_object, self.used_aliases)
  File "D:\Anaconda3\lib\site-packages\django\db\models\sql\query.py", line 1253, in _add_q
    allow_joins=allow_joins, split_subq=split_subq,
  File "D:\Anaconda3\lib\site-packages\django\db\models\sql\query.py", line 1133, in build_filter
    lookups, parts, reffed_expression = self.solve_lookup_type(arg)
  File "D:\Anaconda3\lib\site-packages\django\db\models\sql\query.py", line 1019, in solve_lookup_type
    _, field, _, lookup_parts = self.names_to_path(lookup_splitted, self.get_meta())
  File "D:\Anaconda3\lib\site-packages\django\db\models\sql\query.py", line 1327, in names_to_path
    "Choices are: %s" % (name, ", ".join(available)))
django.core.exceptions.FieldError: Cannot resolve keyword 'name' into field. Choices are: id, lastGeneTime, taskCount, taskName, wc_l
2019-07-04 18:11:24,307 - exception.py[line:124] - ERROR: Internal Server Error: /monitor/index
Traceback (most recent call last):
  File "D:\Anaconda3\lib\site-packages\django\core\handlers\exception.py", line 39, in inner
    response = get_response(request)
  File "D:\Anaconda3\lib\site-packages\django\core\handlers\base.py", line 187, in _get_response
    response = self.process_exception_by_middleware(e, request)
  File "D:\Anaconda3\lib\site-packages\django\core\handlers\base.py", line 185, in _get_response
    response = wrapped_callback(request, *callback_args, **callback_kwargs)
  File "D:\new\07_code_project\mydjango\monitor\views.py", line 27, in index
    if checkTaskRec(name,time):
  File "D:\new\07_code_project\mydjango\monitor\views.py", line 46, in checkTaskRec
    for rec in TaskRec.objects.filter(name=name):
  File "D:\Anaconda3\lib\site-packages\django\db\models\manager.py", line 85, in manager_method
    return getattr(self.get_queryset(), name)(*args, **kwargs)
  File "D:\Anaconda3\lib\site-packages\django\db\models\query.py", line 796, in filter
    return self._filter_or_exclude(False, *args, **kwargs)
  File "D:\Anaconda3\lib\site-packages\django\db\models\query.py", line 814, in _filter_or_exclude
    clone.query.add_q(Q(*args, **kwargs))
  File "D:\Anaconda3\lib\site-packages\django\db\models\sql\query.py", line 1227, in add_q
    clause, _ = self._add_q(q_object, self.used_aliases)
  File "D:\Anaconda3\lib\site-packages\django\db\models\sql\query.py", line 1253, in _add_q
    allow_joins=allow_joins, split_subq=split_subq,
  File "D:\Anaconda3\lib\site-packages\django\db\models\sql\query.py", line 1133, in build_filter
    lookups, parts, reffed_expression = self.solve_lookup_type(arg)
  File "D:\Anaconda3\lib\site-packages\django\db\models\sql\query.py", line 1019, in solve_lookup_type
    _, field, _, lookup_parts = self.names_to_path(lookup_splitted, self.get_meta())
  File "D:\Anaconda3\lib\site-packages\django\db\models\sql\query.py", line 1327, in names_to_path
    "Choices are: %s" % (name, ", ".join(available)))
django.core.exceptions.FieldError: Cannot resolve keyword 'name' into field. Choices are: id, lastGeneTime, taskCount, taskName, wc_l
2019-07-04 18:12:09,988 - views.py[line:30] - WARNING: send Message to User for Warning
2019-07-04 18:12:09,988 - views.py[line:30] - WARNING: send Message to User for Warning
2019-07-04 18:12:31,174 - exception.py[line:124] - ERROR: Internal Server Error: /monitor/index
Traceback (most recent call last):
  File "D:\Anaconda3\lib\site-packages\django\core\handlers\exception.py", line 39, in inner
    response = get_response(request)
  File "D:\Anaconda3\lib\site-packages\django\core\handlers\base.py", line 187, in _get_response
    response = self.process_exception_by_middleware(e, request)
  File "D:\Anaconda3\lib\site-packages\django\core\handlers\base.py", line 185, in _get_response
    response = wrapped_callback(request, *callback_args, **callback_kwargs)
  File "D:\new\07_code_project\mydjango\monitor\views.py", line 27, in index
    if checkTaskRec(name,time):
  File "D:\new\07_code_project\mydjango\monitor\views.py", line 51, in checkTaskRec
    print(rec.name)
AttributeError: 'TaskRec' object has no attribute 'name'
2019-07-04 18:12:31,174 - exception.py[line:124] - ERROR: Internal Server Error: /monitor/index
Traceback (most recent call last):
  File "D:\Anaconda3\lib\site-packages\django\core\handlers\exception.py", line 39, in inner
    response = get_response(request)
  File "D:\Anaconda3\lib\site-packages\django\core\handlers\base.py", line 187, in _get_response
    response = self.process_exception_by_middleware(e, request)
  File "D:\Anaconda3\lib\site-packages\django\core\handlers\base.py", line 185, in _get_response
    response = wrapped_callback(request, *callback_args, **callback_kwargs)
  File "D:\new\07_code_project\mydjango\monitor\views.py", line 27, in index
    if checkTaskRec(name,time):
  File "D:\new\07_code_project\mydjango\monitor\views.py", line 51, in checkTaskRec
    print(rec.name)
AttributeError: 'TaskRec' object has no attribute 'name'
2019-07-04 18:12:58,260 - views.py[line:30] - WARNING: send Message to User for Warning
2019-07-04 18:12:58,260 - views.py[line:30] - WARNING: send Message to User for Warning
2019-07-04 18:15:05,443 - views.py[line:30] - WARNING: send Message to User for Warning
2019-07-04 18:15:05,443 - views.py[line:30] - WARNING: send Message to User for Warning
2019-07-04 18:15:12,007 - views.py[line:30] - WARNING: send Message to User for Warning
2019-07-04 18:15:12,007 - views.py[line:30] - WARNING: send Message to User for Warning
